<?xml version="1.0" encoding="utf-8"?>
<!-- =================================================================================== -->
<!-- |    This document was autogenerated by xacro from ebot_ur5.xacro                 | -->
<!-- |    EDITING THIS FILE BY HAND IS NOT RECOMMENDED                                 | -->
<!-- =================================================================================== -->
<!--  
  Project Name: ebot 
  Created on:   2.10.2020
  Author: ROS team
  Copyright (c) 2020 eYantra IITB 
-->
<robot name="ebot">
  <gazebo>
    <plugin filename="libgazebo_ros_skid_steer_drive.so" name="skid_steer_drive_controller">
      <updateRate>40.0</updateRate>
      <leftFrontJoint>FWLJ</leftFrontJoint>
      <rightFrontJoint>FWRJ</rightFrontJoint>
      <leftRearJoint>RWLJ</leftRearJoint>
      <rightRearJoint>RWRJ</rightRearJoint>
      <wheelSeparation>0.4</wheelSeparation>
      <wheelDiameter>0.2</wheelDiameter>
      <robotBaseFrame>ebot_base</robotBaseFrame>
      <torque>60</torque>
      <topicName>cmd_vel</topicName>
      <commandTopic>cmd_vel</commandTopic>
      <odometryTopic>odom</odometryTopic>
      <odometryFrame>odom</odometryFrame>
      <broadcastTF>true</broadcastTF>
    </plugin>
  </gazebo>
  <gazebo reference="FWL">
    <material>Gazebo/Black</material>
  </gazebo>
  <gazebo reference="FWR">
    <material>Gazebo/Black</material>
  </gazebo>
  <gazebo reference="RWL">
    <material>Gazebo/Black</material>
  </gazebo>
  <gazebo reference="RWR">
    <material>Gazebo/Black</material>
  </gazebo>
  <gazebo reference="ebot_base">
    <material>Gazebo/Grey</material>
  </gazebo>
  <gazebo reference="laser">
    <material>Gazebo/Black</material>
  </gazebo>
  <gazebo reference="camera_link">
    <material>Gazebo/Black</material>
  </gazebo>
  <!--  <gazebo>
    <plugin filename="libgazebo_ros_control.so" name="gazebo_ros_control">
      <legacyModeNS>true</legacyModeNS>
    </plugin>
  </gazebo>
 -->
  <!-- lidar sensor -->
  <!-- using GPU -->
  <!--   <gazebo reference="laser">
    <sensor type="gpu_ray" name="head_hokuyo_sensor">
      <pose>0 0 0 0 0 0</pose>
      <visualize>true</visualize>
      <update_rate>40</update_rate>
      <ray>
        <scan>
          <horizontal>
            <samples>720</samples>
            <resolution>1</resolution>
            <min_angle>-2.35619</min_angle>
            <max_angle>2.35619</max_angle>
          </horizontal>
        </scan>
        <range>
          <min>0.5</min>
          <max>20.0</max>
          <resolution>0.01</resolution>
        </range>
        <noise>
          <type>gaussian</type>
          
          <mean>0.0</mean>
          <stddev>0.01</stddev>
        </noise>
      </ray>
      <plugin name="gazebo_ros_head_hokuyo_controller" filename="libgazebo_ros_gpu_laser.so">
        <topicName>/ebot/laser/scan</topicName>
        <frameName>laser</frameName>
      </plugin>
    </sensor>
  </gazebo> -->
  <!-- using CPU 0.5 to 20m-->
  <gazebo reference="laser">
    <sensor name="head_rplidar_sensor" type="ray">
      <pose>0 0 0 0 0 0</pose>
      <visualize>false</visualize>
      <update_rate>40</update_rate>
      <ray>
        <scan>
          <horizontal>
            <samples>720</samples>
            <resolution>1</resolution>
            <min_angle>-2.35619</min_angle>
            <max_angle>2.35619</max_angle>
          </horizontal>
        </scan>
        <range>
          <min>0.5</min>
          <max>20.0</max>
          <resolution>0.01</resolution>
        </range>
        <noise>
          <type>gaussian</type>
          <mean>0.0</mean>
          <stddev>0.01</stddev>
        </noise>
      </ray>
      <plugin filename="libgazebo_ros_laser.so" name="gazebo_ros_head_rplidar_controller">
        <topicName>/ebot/laser/scan</topicName>
        <frameName>laser</frameName>
      </plugin>
    </sensor>
  </gazebo>
  <!-- intel realsense1 -->
  <gazebo reference="camera_link">
    <sensor name="intelrealsenseD435i" type="depth">
      <always_on>1</always_on>
      <visualize>true</visualize>
      <camera>
        <horizontal_fov>1.047</horizontal_fov>
        <image>
          <width>640</width>
          <height>480</height>
          <format>R8G8B8</format>
        </image>
        <depth_camera>

        </depth_camera>
        <clip>
          <near>0.1</near>
          <far>100</far>
        </clip>
      </camera>
      <plugin filename="libgazebo_ros_openni_kinect.so" name="intelrealsense">
        <alwaysOn>true</alwaysOn>
        <updateRate>10.0</updateRate>
        <cameraName>camera</cameraName>
        <frameName>camera_depth_frame</frameName>
        <imageTopicName>/camera/color/image_raw</imageTopicName>
        <depthImageTopicName>/camera/depth/image_rect_raw</depthImageTopicName>
        <pointCloudTopicName>depth/points</pointCloudTopicName>
        <cameraInfoTopicName>/camera/color/camera_info</cameraInfoTopicName>
        <depthImageCameraInfoTopicName>/camera/depth/camera_info</depthImageCameraInfoTopicName>
        <pointCloudCutoff>0.2</pointCloudCutoff>
        <pointCloudCutoffMax>10.0</pointCloudCutoffMax>
        <hackBaseline>0.07</hackBaseline>
        <distortionK1>0.0</distortionK1>
        <distortionK2>0.0</distortionK2>
        <distortionK3>0.0</distortionK3>
        <distortionT1>0.0</distortionT1>
        <distortionT2>0.0</distortionT2>
        <CxPrime>0.0</CxPrime>
        <Cx>0.0</Cx>
        <Cy>0.0</Cy>
        <focalLength>0.0</focalLength>
      </plugin>
    </sensor>
  </gazebo>
  <!--10  ultrasonic sensor -->
  <!-- xacro for ultrasonic sensor using GPU -->
  <!-- 
<xacro:macro name="ultrasonic_sensor" params="name">
    <gazebo reference="${name}">
    <sensor type="gpu_ray" name="${name}">
      <pose>0 0 0 0 0 0</pose>
      <visualize>false</visualize>
      <update_rate>40</update_rate>
      <ray>
        <scan>
          <horizontal>
            <samples>720</samples>
            <resolution>1</resolution>
            <min_angle>-0.1309</min_angle>
            <max_angle>0.1309</max_angle>
          </horizontal>
        </scan>
        <range>
          <min>0.03</min>
          <max>4.5</max>
          <resolution>0.01</resolution>
        </range>
        <noise>
          <type>gaussian</type>
          
          <mean>0.0</mean>
          <stddev>0.01</stddev>
        </noise>
      </ray>
      <plugin name="ultrasonic_sensor" filename="libgazebo_ros_gpu_laser.so">
        <topicName>/ebot/${name}/scan</topicName>
        <frameName>${name}_ultrasonic_sensor</frameName>
      </plugin>
    </sensor>
  </gazebo>
</xacro:macro>-->
  <!-- using CPU -->
  <!-- <xacro:macro name="ultrasonic_sensor" params="name">
    <gazebo reference="${name}">

    <sensor type="ray" name="head_rplidar_sensor">
      <pose>0 0 0 0 0 0</pose>
      <visualize>false</visualize>
      <update_rate>40</update_rate>
      <ray>
        <scan>
          <horizontal>
            <samples>720</samples>
            <resolution>1</resolution>
            <min_angle>-0.1309</min_angle>
            <max_angle>0.1309</max_angle>
          </horizontal>
        </scan>
        <range>
          <min>0.03</min>
          <max>4.5</max>
          <resolution>0.01</resolution>
        </range>
        <noise>
          <type>gaussian</type>
          <mean>0.0</mean>
          <stddev>0.01</stddev>
        </noise>
      </ray>
      <plugin name="ultrasonic_sensor" filename="libgazebo_ros_laser.so">
        <topicName>/ebot/${name}/scan</topicName>
        <frameName>${name}_ultrasonic_sensor</frameName>
      </plugin>
    </sensor>
  </gazebo> 
  </xacro:macro> 

<xacro:ultrasonic_sensor name="FUS1"/> 
<xacro:ultrasonic_sensor name="FUS2"/> 
<xacro:ultrasonic_sensor name="FUS3"/> 
<xacro:ultrasonic_sensor name="FUS4"/> 
<xacro:ultrasonic_sensor name="RUS5"/> 
<xacro:ultrasonic_sensor name="RUS6"/> 
<xacro:ultrasonic_sensor name="RHUS7"/> 
<xacro:ultrasonic_sensor name="RHUS9"/> 
<xacro:ultrasonic_sensor name="LHUS9"/> 
<xacro:ultrasonic_sensor name="LHUS10"/> -->
  <!-- imu -->
  <gazebo reference="imu_link">
    <gravity>true</gravity>
    <sensor name="imu_sensor" type="imu">
      <always_on>true</always_on>
      <update_rate>100</update_rate>
      <visualize>true</visualize>
      <topic>__default_topic__</topic>
      <plugin filename="libgazebo_ros_imu_sensor.so" name="imu_plugin">
        <topicName>imu</topicName>
        <bodyName>imu_link</bodyName>
        <updateRateHZ>10.0</updateRateHZ>
        <gaussianNoise>0.0</gaussianNoise>
        <xyzOffset>0 0 0</xyzOffset>
        <rpyOffset>0 0 0</rpyOffset>
        <frameName>imu_link</frameName>
        <initialOrientationAsReference>false</initialOrientationAsReference>
      </plugin>
      <pose>0 0 0 0 0 0</pose>
    </sensor>
  </gazebo>
  <!--   base of the robot -->
  <link name="ebot_base">
    <inertial>
      <origin rpy="0 0 0" xyz="0 0.0 0.12"/>
      <mass value="28"/>
      <!--   <inertia
        ixx="0.0077465"
        ixy="0.0005698"
        ixz="0.0049745"
        iyy="0.03055"
        iyz="-4.0532E-05"
        izz="0.030588" /> -->
      <inertia ixx="0.356" ixy="0" ixz="0" iyy="0.9443" iyz="0" izz="1.008"/>
    </inertial>
    <visual>
      <origin rpy="0 0 0" xyz="0 0 0"/>
      <geometry>
        <mesh filename="package://ebot_description/meshes/chassis.STL"/>
      </geometry>
      <material name="">
        <color rgba="0.79216 0.81961 0.93333 1"/>
      </material>
    </visual>
    <collision>
      <origin rpy="0 0 0" xyz="0 0.0 0.12"/>
      <geometry>
        <box size="0.585 0.30 0.25"/>
      </geometry>
    </collision>
  </link>
  <!-- front wheel right -->
  <link name="FWR">
    <inertial>
      <origin rpy="0 0 0" xyz="6.6592E-05 0.025016 -1.3483E-06"/>
      <mass value="0.7"/>
      <!--  <inertia
        ixx="0.0012203"
        ixy="-1.8327E-07"
        ixz="1.356E-08"
        iyy="0.0022215"
        iyz="3.3883E-09"
        izz="0.001221" /> -->
      <inertia ixx="0.003" ixy="0" ixz="0" iyy="0.0030" iyz="0" izz="0.0035"/>
    </inertial>
    <visual>
      <origin rpy="0 0 0" xyz="0 0 0"/>
      <geometry>
        <mesh filename="package://ebot_description/meshes/FWR.STL"/>
      </geometry>
      <material name="">
        <color rgba="0.79216 0.81961 0.93333 1"/>
      </material>
    </visual>
    <collision>
      <origin rpy="1.57 1.57 0" xyz="0 0.025 0"/>
      <geometry>
        <cylinder length="0.05" radius="0.1"/>
      </geometry>
    </collision>
  </link>
  <joint name="FWRJ" type="continuous">
    <origin rpy="-3.14159265358979 0.911096362238563 0.00679706827343889" xyz="0.202539503068943 -0.189027702306049 0.0449999999999943"/>
    <parent link="ebot_base"/>
    <child link="FWR"/>
    <axis xyz="0 -1 0"/>
  </joint>
  <!-- front wheel left -->
  <link name="FWL">
    <inertial>
      <origin rpy="0 0 0" xyz="6.6594E-05 0.025016 -1.349E-06"/>
      <mass value="0.7"/>
      <!--    <inertia
        ixx="0.0012203"
        ixy="-1.8333E-07"
        ixz="1.3546E-08"
        iyy="0.0022215"
        iyz="3.3744E-09"
        izz="0.001221" /> -->
      <inertia ixx="0.003" ixy="0" ixz="0" iyy="0.0030" iyz="0" izz="0.0035"/>
    </inertial>
    <visual>
      <origin rpy="0 0 0" xyz="0 0 0"/>
      <geometry>
        <mesh filename="package://ebot_description/meshes/FWL.STL"/>
      </geometry>
      <material name="">
        <color rgba="0.79216 0.81961 0.93333 1"/>
      </material>
    </visual>
    <collision>
      <origin rpy="1.57 1.57 0" xyz="0 0.025 0"/>
      <geometry>
        <cylinder length="0.05" radius="0.1"/>
      </geometry>
    </collision>
  </link>
  <joint name="FWLJ" type="continuous">
    <origin rpy="0 0 0.00679706827344463" xyz="0.199948480594093 0.192163491981716 0.0450000000000047"/>
    <parent link="ebot_base"/>
    <child link="FWL"/>
    <axis xyz="0 1 0"/>
  </joint>
  <!--   rear wheel right -->
  <link name="RWR">
    <inertial>
      <origin rpy="0 0 0" xyz="6.6592E-05 0.025016 -1.3483E-06"/>
      <mass value="0.7"/>
      <!--     <inertia
        ixx="0.0012203"
        ixy="-1.8327E-07"
        ixz="1.356E-08"
        iyy="0.0022215"
        iyz="3.3883E-09"
        izz="0.001221" /> -->
      <inertia ixx="0.003" ixy="0" ixz="0" iyy="0.0030" iyz="0" izz="0.0035"/>
    </inertial>
    <visual>
      <origin rpy="0 0 0" xyz="0 0 0"/>
      <geometry>
        <mesh filename="package://ebot_description/meshes/RWR.STL"/>
      </geometry>
      <material name="">
        <color rgba="0.79216 0.81961 0.93333 1"/>
      </material>
    </visual>
    <collision>
      <origin rpy="1.57 1.57 0" xyz="0 0.025 0"/>
      <geometry>
        <cylinder length="0.05" radius="0.1"/>
      </geometry>
    </collision>
  </link>
  <joint name="RWRJ" type="continuous">
    <origin rpy="-3.14159265358979 0.544912084409921 0.00679706827344312" xyz="-0.197451256939211 -0.191746508680447 0.044999999999993"/>
    <parent link="ebot_base"/>
    <child link="RWR"/>
    <axis xyz="0 -1 0"/>
  </joint>
  <!--   rear wheel left -->
  <link name="RWL">
    <inertial>
      <origin rpy="0 0 0" xyz="6.6594E-05 0.025016 -1.349E-06"/>
      <mass value="0.7"/>
      <!--  <inertia
        ixx="0.0012203"
        ixy="-1.8333E-07"
        ixz="1.3546E-08"
        iyy="0.0022215"
        iyz="3.3744E-09"
        izz="0.001221" /> -->
      <inertia ixx="0.003" ixy="0" ixz="0" iyy="0.0030" iyz="0" izz="0.0035"/>
    </inertial>
    <visual>
      <origin rpy="0 0 0" xyz="0 0 0"/>
      <geometry>
        <mesh filename="package://ebot_description/meshes/RWL.STL"/>
      </geometry>
      <material name="">
        <color rgba="0.79216 0.81961 0.93333 1"/>
      </material>
    </visual>
    <collision>
      <origin rpy="1.57 1.57 0" xyz="0 0.025 0"/>
      <geometry>
        <cylinder length="0.05" radius="0.1"/>
      </geometry>
    </collision>
  </link>
  <joint name="RWLJ" type="continuous">
    <origin rpy="0 0 0.00679706827344463" xyz="-0.200042279414009 0.189444685607321 0.0449999999999969"/>
    <parent link="ebot_base"/>
    <child link="RWL"/>
    <axis xyz="0 1 0"/>
  </joint>
  <!-- ,,,,,,,,,,,,,,,,,,,,,,,,,,,,,,,,,,,,,,,,,,,,,,,,,,,,,,,,,,,,,, -->
  <!-- Sensors link -->
  <!-- intel real sense -->
  <!--  <link
    name="NAVRS">
    <inertial>
      <origin
        xyz="0.0016823 2.5257E-06 -0.013272"
        rpy="0 0 0" />
      <mass
        value="0.038191" />
      <inertia
        ixx="2.1117E-06"
        ixy="-8.0047E-09"
        ixz="4.5113E-08"
        iyy="2.2257E-05"
        iyz="-1.3011E-08"
        izz="2.3574E-05" />
    </inertial>
    <visual>
      <origin
        xyz="0 0 0"
        rpy="0 0 0" />
      <geometry>
        <mesh
          filename="package://ebot_description/meshes/NAVRS.STL" />
      </geometry>
      <material
        name="">
        <color
          rgba="0.79216 0.81961 0.93333 1" />
      </material>
    </visual>
    <collision>
      <origin
        xyz="0 0 0"
        rpy="0 0 0" />
      <geometry>
        <mesh
          filename="package://ebot_description/meshes/NAVRS.STL" />
      </geometry>
    </collision>
  </link>
  <joint
    name="NAVRSJ"
    type="fixed">
    <origin
      xyz="0.277944460576403 0.00208437301780086 0.0230507258091751"
      rpy="1.22173047639603 0 1.57759339506835" />
    <parent
      link="ebot_base" />
    <child
      link="NAVRS" />
    <axis
      xyz="0 0 0" />
  </joint> -->
  <!-- Intel real sense Camera for 3D mapping-->
  <joint name="realsensejoint" type="fixed">
    <axis xyz="0 0 0"/>
    <origin rpy="0 0 0" xyz="0.277944460576403 0.00208437301780086 0.0230507258091751"/>
    <parent link="ebot_base"/>
    <child link="camera_link"/>
  </joint>
  <link name="camera_link">
    <collision>
      <origin rpy="0 0 0" xyz="0.02 0 0"/>
      <geometry>
        0
        
        <box size="0.001 0.001 0.001"/>
      </geometry>
    </collision>
    <visual>
      <origin rpy="1.5707 0 1.5707" xyz="0 0 0"/>
      <geometry>
        <mesh filename="package://ebot_description/meshes/NAVRS.STL"/>
      </geometry>
    </visual>
    <inertial>
      <mass value="1e-5"/>
      <origin rpy="0 0 0" xyz="0 0 0"/>
      <inertia ixx="0" ixy="0" ixz="0" iyy="0" iyz="0" izz="0"/>
    </inertial>
  </link>
  <joint name="camera_optical_joint" type="fixed">
    <origin rpy="-1.57079632679 0 -1.57079632679" xyz="0 0 0"/>
    <parent link="camera_link"/>
    <child link="camera_rgb_frame"/>
  </joint>
  <link name="camera_rgb_frame">
  </link>
  <joint name="camera_depth_joint" type="fixed">
    <origin rpy="-1.57079632679 0 -1.57079632679" xyz="0 0 0"/>
    <parent link="camera_link"/>
    <child link="camera_depth_frame"/>
  </joint>
  <link name="camera_depth_frame">
  </link>
  <!-- intel real sense front-->
  <!--  <link
    name="FRS">
    <inertial>
      <origin
        xyz="0.00168231679195632 2.4803948074914E-06 -0.0132722904550864"
        rpy="0 0 0" />
      <mass
        value="0.0381911728098315" />
      <inertia
        ixx="2.11168824113949E-06"
        ixy="-8.02356855906873E-09"
        ixz="4.5112402633483E-08"
        iyy="2.22571079364103E-05"
        iyz="-1.30126771993394E-08"
        izz="2.35737411331488E-05" />
    </inertial>
    <visual>
      <origin
        xyz="0 0 0"
        rpy="0 0 0" />
      <geometry>
        <mesh
          filename="package://ebot_description/meshes/FRS.STL" />
      </geometry>
      <material
        name="">
        <color
          rgba="0.792156862745098 0.819607843137255 0.933333333333333 1" />
      </material>
    </visual>
    <collision>
      <origin
        xyz="0 0 0"
        rpy="0 0 0" />
      <geometry>
        <mesh
          filename="package://ebot_description/meshes/FRS.STL" />
      </geometry>
    </collision>
  </link>


  <joint
    name="FRSJ"
    type="fixed">
    <origin
      xyz="0.284268798438206 -0.00037145817769214 0.274149821359369"
      rpy="1.5707963267949 0 1.57759339506835" />
    <parent
      link="ebot_base" />
    <child
      link="FRS" />
    <axis
      xyz="0 0 0" />
  </joint> -->
  <!-- GPS antenna -->
  <!-- <link
    name="RANT">
    <inertial>
      <origin
        xyz="0.028154 2.1259E-10 -0.001156"
        rpy="0 0 0" />
      <mass
        value="0.029557" />
      <inertia
        ixx="9.1349E-06"
        ixy="1.0072E-15"
        ixz="7.5859E-08"
        iyy="9.2077E-06"
        iyz="1.039E-13"
        izz="2.5426E-06" />
    </inertial>
    <visual>
      <origin
        xyz="0 0 0"
        rpy="0 0 0" />
      <geometry>
        <mesh
          filename="package://ebot_description/meshes/RANT.STL" />
      </geometry>
      <material
        name="">
        <color
          rgba="0.50196 0.50196 0.50196 1" />
      </material>
    </visual>
    <collision>
      <origin
        xyz="0 0 0"
        rpy="0 0 0" />
      <geometry>
        <mesh
          filename="package://ebot_description/meshes/RANT.STL" />
      </geometry>
    </collision>
  </link>
  <joint
    name="RANTJ"
    type="fixed">
    <origin
      xyz="-0.235318969789988 -0.136067282959491 0.313349821423561"
      rpy="0 0 0.00679706827344463" />
    <parent
      link="ebot_base" />
    <child
      link="RANT" />
    <axis
      xyz="0 0 0" />
  </joint>


  <link
    name="LANT">
    <inertial>
      <origin
        xyz="0.0281543406508122 2.12586531711523E-10 -0.00115603773859746"
        rpy="0 0 0" />
      <mass
        value="0.029557338331917" />
      <inertia
        ixx="9.13492298014281E-06"
        ixy="1.00717079208302E-15"
        ixz="7.58587832004E-08"
        iyy="9.20770654154307E-06"
        iyz="1.03900822067537E-13"
        izz="2.54259101029362E-06" />
    </inertial>
    <visual>
      <origin
        xyz="0 0 0"
        rpy="0 0 0" />
      <geometry>
        <mesh
          filename="package://ebot_description/meshes/LANT.STL" />
      </geometry>
      <material
        name="">
        <color
          rgba="0.501960784313725 0.501960784313725 0.501960784313725 1" />
      </material>
    </visual>
    <collision>
      <origin
        xyz="0 0 0"
        rpy="0 0 0" />
      <geometry>
        <mesh
          filename="package://ebot_description/meshes/LANT.STL" />
      </geometry>
    </collision>
  </link>
  <joint
    name="LANTJ"
    type="fixed">
    <origin
      xyz="-0.237145020166288 0.132581225705085 0.313349821423561"
      rpy="0 0 0.00679706827344463" />
    <parent
      link="ebot_base" />
    <child
      link="LANT" />
    <axis
      xyz="0 0 0" />
  </joint> -->
  <!--  Rear real sense -->
  <!--  <link
    name="RRS">
    <inertial>
      <origin
        xyz="0.00168231639732897 2.48028940916245E-06 -0.0132722905610603"
        rpy="0 0 0" />
      <mass
        value="0.0381911723565768" />
      <inertia
        ixx="2.11168822440936E-06"
        ixy="-8.02357331414088E-09"
        ixz="4.51124029003091E-08"
        iyy="2.2257107947401E-05"
        iyz="-1.30126755374412E-08"
        izz="2.35737411275859E-05" />
    </inertial>
    <visual>
      <origin
        xyz="0 0 0"
        rpy="0 0 0" />
      <geometry>
        <mesh
          filename="package://ebot_description/meshes/RRS.STL" />
      </geometry>
      <material
        name="">
        <color
          rgba="0.792156862745098 0.819607843137255 0.933333333333333 1" />
      </material>
    </visual>
    <collision>
      <origin
        xyz="0 0 0"
        rpy="0 0 0" />
      <geometry>
        <mesh
          filename="package://ebot_description/meshes/RRS.STL" />
      </geometry>
    </collision>
  </link>
  <joint
    name="RRSJ"
    type="fixed">
    <origin
      xyz="-0.281925175358234 0.000787397429290185 0.274149821429193"
      rpy="1.5707963267949 0 -1.56399925852145" />
    <parent
      link="ebot_base" />
    <child
      link="RRS" />
    <axis
      xyz="0 0 0" />
  </joint> -->
  <!-- LIDAR -->
  <link name="laser">
    <origin rpy="0 0 0" xyz="0 0 0"/>
    <inertial>
      <mass value="0.09"/>
      <inertia ixx="4.275e-05" ixy="0" ixz="0" iyy="4.275e-05" iyz="0" izz="5.5125e-05"/>
    </inertial>
    <collision>
      <origin rpy="0 0 0" xyz="0 0 0"/>
      <geometry>
        <cylinder length="0.040" radius="0.030"/>
      </geometry>
    </collision>
    <visual>
      <origin rpy="0 0 0" xyz="0 0 0"/>
      <geometry>
        <cylinder length="0.040" radius="0.030"/>
      </geometry>
    </visual>
  </link>
  <joint name="rplidar_joint" type="fixed">
    <axis xyz="0 1 0"/>
    <origin rpy="0 0 0.00679706827344463" xyz="0.255540836099039 0 0.18"/>
    <parent link="ebot_base"/>
    <child link="laser"/>
    <limit effort="1000" lower="0" upper="6.28" velocity="100"/>
    <axis rpy="0 0 0" xyz="0.02 0 0.178"/>
    <joint_properties damping="5.0" friction="1.0"/>
  </joint>
  <!-- front ultrasonic sensor 1-->
  <link name="FUS1">
    <inertial>
      <origin rpy="0 0 0" xyz="-0.00265918092876655 2.08166817117217E-17 0.0100193625139959"/>
      <mass value="0.0152532066391543"/>
      <inertia ixx="4.77814992940302E-06" ixy="-2.01819824421892E-21" ixz="2.64657807499124E-08" iyy="1.003384637723E-06" iyz="-8.80528876343328E-21" izz="4.55679776636487E-06"/>
    </inertial>
    <visual>
      <origin rpy="0 0 0" xyz="0 0 0"/>
      <geometry>
        <mesh filename="package://ebot_description/meshes/FUS1.STL"/>
      </geometry>
      <material name="">
        <color rgba="0.250980392156863 0.250980392156863 0.250980392156863 1"/>
      </material>
    </visual>
    <collision>
      <origin rpy="0 0 0" xyz="0 0 0"/>
      <geometry>
        <!--  <mesh
          filename="package://ebot_description/meshes/FUS1.STL" /> -->
        <box size="0.019 0.057 0.028"/>
      </geometry>
    </collision>
  </link>
  <joint name="FUS1J" type="fixed">
    <origin rpy="-1.5707963267949 0 0.00679706827344463" xyz="0.297825909825268 -0.157279305693451 0.0977263808983278"/>
    <parent link="ebot_base"/>
    <child link="FUS1"/>
    <axis xyz="0 0 0"/>
  </joint>
  <!-- front ultrasonic sensor 2 -->
  <link name="FUS2">
    <inertial>
      <origin rpy="0 0 0" xyz="-0.0026592 1.9949E-17 0.010019"/>
      <mass value="0.015253"/>
      <inertia ixx="4.7781E-06" ixy="-2.0925E-21" ixz="2.6466E-08" iyy="1.0034E-06" iyz="-9.4695E-21" izz="4.5568E-06"/>
    </inertial>
    <visual>
      <origin rpy="0 0 0" xyz="0 0 0"/>
      <geometry>
        <mesh filename="package://ebot_description/meshes/FUS2.STL"/>
      </geometry>
      <material name="">
        <color rgba="0.25098 0.25098 0.25098 1"/>
      </material>
    </visual>
    <collision>
      <origin rpy="0 0 0" xyz="0 0 0"/>
      <geometry>
        <!-- <mesh
          filename="package://ebot_description/meshes/FUS2.STL" /> -->
        <box size="0.019 0.057 0.028"/>
      </geometry>
    </collision>
  </link>
  <joint name="FUS2J" type="fixed">
    <origin rpy="-1.5707963267949 0 0.00679706827344463" xyz="0.295786805044471 0.142713764312663 0.0977263808983286"/>
    <parent link="ebot_base"/>
    <child link="FUS2"/>
    <axis xyz="0 0 0"/>
  </joint>
  <!--   front ultrasonic sensor 3 -->
  <link name="FUS3">
    <inertial>
      <origin rpy="0 0 0" xyz="-0.0026592 5.5511E-17 0.010019"/>
      <mass value="0.015253"/>
      <inertia ixx="4.7781E-06" ixy="2.7832E-20" ixz="2.6466E-08" iyy="1.0034E-06" iyz="1.4502E-20" izz="4.5568E-06"/>
    </inertial>
    <visual>
      <origin rpy="0 0 0" xyz="0 0 0"/>
      <geometry>
        <mesh filename="package://ebot_description/meshes/FUS3.STL"/>
      </geometry>
      <material name="">
        <color rgba="0.25098 0.25098 0.25098 1"/>
      </material>
    </visual>
    <collision>
      <origin rpy="0 0 0" xyz="0 0 0"/>
      <geometry>
        <!--   <mesh
          filename="package://ebot_description/meshes/FUS3.STL" /> -->
        <box size="0.019 0.057 0.028"/>
      </geometry>
    </collision>
  </link>
  <joint name="FUS3J" type="fixed">
    <origin rpy="0 0.785398163397449 0.00679706827344116" xyz="0.27274874909921 -0.0749478536996718 0.0424745013517897"/>
    <parent link="ebot_base"/>
    <child link="FUS3"/>
    <axis xyz="0 0 0"/>
  </joint>
  <!--   front ultrasonic sensor 4 -->
  <link name="FUS4">
    <inertial>
      <origin rpy="0 0 0" xyz="-0.00265918092876644 6.93889390390723E-17 0.0100193625139959"/>
      <mass value="0.0152532066391543"/>
      <inertia ixx="4.77814992940302E-06" ixy="2.8163959262392E-20" ixz="2.64657807499109E-08" iyy="1.003384637723E-06" iyz="2.09456577324828E-20" izz="4.55679776636487E-06"/>
    </inertial>
    <visual>
      <origin rpy="0 0 0" xyz="0 0 0"/>
      <geometry>
        <mesh filename="package://ebot_description/meshes/FUS4.STL"/>
      </geometry>
      <material name="">
        <color rgba="0.250980392156863 0.250980392156863 0.250980392156863 1"/>
      </material>
    </visual>
    <collision>
      <origin rpy="0 0 0" xyz="0 0 0"/>
      <geometry>
        <!--  <mesh
          filename="package://ebot_description/meshes/FUS4.STL" /> -->
        <box size="0.019 0.057 0.028"/>
      </geometry>
    </collision>
  </link>
  <joint name="FUS4J" type="fixed">
    <origin rpy="0 0.785398163397449 0.00679706827344116" xyz="0.271702008645067 0.0790485889034664 0.0424745013517894"/>
    <parent link="ebot_base"/>
    <child link="FUS4"/>
    <axis xyz="0 0 0"/>
  </joint>
  <!--   Rear ultra sonic sensor 5 -->
  <link name="RUS5">
    <inertial>
      <origin rpy="0 0 0" xyz="-0.0026592 2.6021E-17 0.010019"/>
      <mass value="0.015253"/>
      <inertia ixx="4.7781E-06" ixy="-1.9723E-21" ixz="2.6466E-08" iyy="1.0034E-06" iyz="-7.7105E-21" izz="4.5568E-06"/>
    </inertial>
    <visual>
      <origin rpy="0 0 0" xyz="0 0 0"/>
      <geometry>
        <mesh filename="package://ebot_description/meshes/RUS5.STL"/>
      </geometry>
      <material name="">
        <color rgba="0.25098 0.25098 0.25098 1"/>
      </material>
    </visual>
    <collision>
      <origin rpy="0 0 0" xyz="0 0 0"/>
      <geometry>
        <!--  <mesh
          filename="package://ebot_description/meshes/RUS5.STL" /> -->
        <box size="0.019 0.057 0.028"/>
      </geometry>
    </collision>
  </link>
  <joint name="RUS5J" type="fixed">
    <origin rpy="-1.5707963267949 0 -3.13479558531634" xyz="-0.29532868617037 0.157696288994793 0.0977029437251515"/>
    <parent link="ebot_base"/>
    <child link="RUS5"/>
    <axis xyz="0 0 0"/>
  </joint>
  <!--   Rear ultra sonic sensor 6 -->
  <link name="RUS6">
    <inertial>
      <origin rpy="0 0 0" xyz="-0.00265918092876644 2.34187669256869E-17 0.0100193625139959"/>
      <mass value="0.0152532066391543"/>
      <inertia ixx="4.77814992940302E-06" ixy="-1.34867897211379E-21" ixz="2.64657807499114E-08" iyy="1.003384637723E-06" iyz="-1.29818552470248E-20" izz="4.55679776636487E-06"/>
    </inertial>
    <visual>
      <origin rpy="0 0 0" xyz="0 0 0"/>
      <geometry>
        <mesh filename="package://ebot_description/meshes/RUS6.STL"/>
      </geometry>
      <material name="">
        <color rgba="0.250980392156863 0.250980392156863 0.250980392156863 1"/>
      </material>
    </visual>
    <collision>
      <origin rpy="0 0 0" xyz="0 0 0"/>
      <geometry>
        <!--  <mesh
          filename="package://ebot_description/meshes/RUS6.STL" /> -->
        <box size="0.019 0.057 0.028"/>
      </geometry>
    </collision>
  </link>
  <joint name="RUS6J" type="fixed">
    <origin rpy="-1.5707963267949 0 -3.13479558531634" xyz="-0.293289581389573 -0.14229678101132 0.0977029437251508"/>
    <parent link="ebot_base"/>
    <child link="RUS6"/>
    <axis xyz="0 0 0"/>
  </joint>
  <!--   Right ultra sonic sensor 7 -->
  <link name="RHUS7">
    <inertial>
      <origin rpy="0 0 0" xyz="-0.00265918092876641 1.23570598198341E-12 0.0100193625139959"/>
      <mass value="0.0152532066391543"/>
      <inertia ixx="4.77814992940302E-06" ixy="3.27217392921119E-18" ixz="2.64657807499107E-08" iyy="1.003384637723E-06" iyz="4.38229124201629E-16" izz="4.55679776636487E-06"/>
    </inertial>
    <visual>
      <origin rpy="0 0 0" xyz="0 0 0"/>
      <geometry>
        <mesh filename="package://ebot_description/meshes/RHUS7.STL"/>
      </geometry>
      <material name="">
        <color rgba="0.250980392156863 0.250980392156863 0.250980392156863 1"/>
      </material>
    </visual>
    <collision>
      <origin rpy="0 0 0" xyz="0 0 0"/>
      <geometry>
        <!--  <mesh
          filename="package://ebot_description/meshes/RHUS7.STL" /> -->
        <box size="0.019 0.057 0.028"/>
      </geometry>
    </collision>
  </link>
  <joint name="RHUS7J" type="fixed">
    <origin rpy="0 0 -1.56399925852145" xyz="-0.17860231149778 -0.148017381955971 0.189449821416576"/>
    <parent link="ebot_base"/>
    <child link="RHUS7"/>
    <axis xyz="0 0 0"/>
  </joint>
  <!--   Right ultra sonicsensor 9 -->
  <link name="RHUS9">
    <inertial>
      <origin rpy="0 0 0" xyz="-0.0026592 6.9389E-18 0.010019"/>
      <mass value="0.015253"/>
      <inertia ixx="4.7781E-06" ixy="1.6008E-20" ixz="2.6466E-08" iyy="1.0034E-06" iyz="-1.185E-20" izz="4.5568E-06"/>
    </inertial>
    <visual>
      <origin rpy="0 0 0" xyz="0 0 0"/>
      <geometry>
        <mesh filename="package://ebot_description/meshes/RHUS9.STL"/>
      </geometry>
      <material name="">
        <color rgba="0.25098 0.25098 0.25098 1"/>
      </material>
    </visual>
    <collision>
      <origin rpy="0 0 0" xyz="0 0 0"/>
      <geometry>
        <!-- <mesh
          filename="package://ebot_description/meshes/RHUS9.STL" /> -->
        <box size="0.019 0.057 0.028"/>
      </geometry>
    </collision>
  </link>
  <joint name="RHUS9J" type="fixed">
    <origin rpy="-0.00186883076605492 0.123098458475999 -0.786255211903501" xyz="0.141804076845343 -0.0977216096162414 0.196076309026378"/>
    <parent link="ebot_base"/>
    <child link="RHUS9"/>
    <axis xyz="0 0 0"/>
  </joint>
  <!--   Left ultra sonic sensor 9 -->
  <link name="LHUS9">
    <inertial>
      <origin rpy="0 0 0" xyz="-0.00265918092876642 -1.2353174039248E-12 0.0100193625139958"/>
      <mass value="0.0152532066391543"/>
      <inertia ixx="4.77814992940302E-06" ixy="-3.2538981368926E-18" ixz="2.64657807499116E-08" iyy="1.003384637723E-06" iyz="-4.38135627183199E-16" izz="4.55679776636487E-06"/>
    </inertial>
    <visual>
      <origin rpy="0 0 0" xyz="0 0 0"/>
      <geometry>
        <mesh filename="package://ebot_description/meshes/LHUS9.STL"/>
      </geometry>
      <material name="">
        <color rgba="0.250980392156863 0.250980392156863 0.250980392156863 1"/>
      </material>
    </visual>
    <collision>
      <origin rpy="0 0 0" xyz="0 0 0"/>
      <geometry>
        <!--   <mesh
          filename="package://ebot_description/meshes/LHUS9.STL" /> -->
        <box size="0.019 0.057 0.028"/>
      </geometry>
    </collision>
  </link>
  <joint name="LHUS9J" type="fixed">
    <origin rpy="0 0 1.57759339506834" xyz="-0.180600634182961 0.14597582665002 0.189449821416576"/>
    <parent link="ebot_base"/>
    <child link="LHUS9"/>
    <axis xyz="0 0 0"/>
  </joint>
  <!--   left ultra sonic sensor 10 -->
  <link name="LHUS10">
    <inertial>
      <origin rpy="0 0 0" xyz="-0.0026592 -2.0817E-17 0.010019"/>
      <mass value="0.015253"/>
      <inertia ixx="4.7781E-06" ixy="1.1539E-20" ixz="2.6466E-08" iyy="1.0034E-06" iyz="-1.2651E-20" izz="4.5568E-06"/>
    </inertial>
    <visual>
      <origin rpy="0 0 0" xyz="0 0 0"/>
      <geometry>
        <mesh filename="package://ebot_description/meshes/LHUS10.STL"/>
      </geometry>
      <material name="">
        <color rgba="0.25098 0.25098 0.25098 1"/>
      </material>
    </visual>
    <collision>
      <origin rpy="0 0 0" xyz="0 0 0"/>
      <geometry>
        <!-- <mesh
          filename="package://ebot_description/meshes/LHUS10.STL" /> -->
        <box size="0.019 0.057 0.028"/>
      </geometry>
    </collision>
  </link>
  <joint name="LHUS10J" type="fixed">
    <origin rpy="0.00186883076604301 0.123098458475999 0.799849348450393" xyz="0.14045985551618 0.10004021562239 0.196076309026377"/>
    <parent link="ebot_base"/>
    <child link="LHUS10"/>
    <axis xyz="0 0 0"/>
  </joint>
  <!-- IMU -->
  <link name="imu_link">
    <collision>
      <origin rpy="0 0 0" xyz="0 0 0"/>
      <geometry>
        <box size="0.02 0.015 0.008"/>
      </geometry>
    </collision>
    <visual>
      <origin rpy="0 0 0" xyz="0 0 0"/>
      <geometry>
        <box size="0.02 0.015 0.008"/>
      </geometry>
    </visual>
    <inertial>
      <mass value="1e-5"/>
      <origin rpy="0 0 0" xyz="0 0 0"/>
      <inertia ixx="0" ixy="0" ixz="0" iyy="0" iyz="0" izz="0"/>
    </inertial>
  </link>
  <joint name="imujoint" type="fixed">
    <origin rpy="0 0 0" xyz="0 0 0.2"/>
    <parent link="ebot_base"/>
    <child link="imu_link"/>
    <axis xyz="0 0 0"/>
  </joint>
  <!-- <transmission name="front_left_trans">
  <type>transmission_interface/SimpleTransmission</type>
  <joint name="FWLJ">
    <hardwareInterface>hardware_interface/VelocityJointInterface</hardwareInterface>
  </joint>
  <actuator name="Front_Left_Motor">
    <hardwareInterface>hardware_interface/VelocityJointInterface</hardwareInterface>
    <mechanicalReduction>1</mechanicalReduction>
  </actuator>
</transmission>

<transmission name="front_right_trans">
  <type>transmission_interface/SimpleTransmission</type>
  <joint name="FWRJ">
    <hardwareInterface>hardware_interface/VelocityJointInterface</hardwareInterface>
  </joint>
  <actuator name="Front_Right_Motor">
    <hardwareInterface>hardware_interface/VelocityJointInterface</hardwareInterface>
    <mechanicalReduction>1</mechanicalReduction>
  </actuator>
</transmission>

<transmission name="back_left_trans">
  <type>transmission_interface/SimpleTransmission</type>
  <joint name="RWLJ">
    <hardwareInterface>hardware_interface/VelocityJointInterface</hardwareInterface>
  </joint>
  <actuator name="Back_Left_Motor">
    <hardwareInterface>hardware_interface/VelocityJointInterface</hardwareInterface>
    <mechanicalReduction>1</mechanicalReduction>
  </actuator>
</transmission>

<transmission name="back_right_trans">
  <type>transmission_interface/SimpleTransmission</type>
  <joint name="RWRJ">
    <hardwareInterface>hardware_interface/VelocityJointInterface</hardwareInterface>
  </joint>
  <actuator name="Back_Right_Motor">
    <hardwareInterface>hardware_interface/VelocityJointInterface</hardwareInterface>
    <mechanicalReduction>1</mechanicalReduction>
  </actuator>
</transmission>  -->
  <gazebo>
    <plugin filename="libgazebo_ros_control.so" name="ros_control">
      <!-- 	<robotNamespace>/MYROBOT</robotNamespace>
    <robotSimType>gazebo_ros_control/DefaultRobotHWSim</robotSimType> -->
    </plugin>
    <!--
    <plugin name="gazebo_ros_power_monitor_controller" filename="libgazebo_ros_power_monitor.so">
      <alwaysOn>true</alwaysOn>
      <updateRate>1.0</updateRate>
      <timeout>5</timeout>
      <powerStateTopic>power_state</powerStateTopic>
      <powerStateRate>10.0</powerStateRate>
      <fullChargeCapacity>87.78</fullChargeCapacity>     
      <dischargeRate>-474</dischargeRate>
      <chargeRate>525</chargeRate>
      <dischargeVoltage>15.52</dischargeVoltage>
      <chargeVoltage>16.41</chargeVoltage>
    </plugin>
-->
  </gazebo>
  <!-- measured from model -->
  <!--property name="shoulder_height" value="0.089159" /-->
  <!--property name="shoulder_offset" value="0.13585" /-->
  <!-- shoulder_offset - elbow_offset + wrist_1_length = 0.10915 -->
  <!--property name="upper_arm_length" value="0.42500" /-->
  <!--property name="elbow_offset" value="0.1197" /-->
  <!-- CAD measured -->
  <!--property name="forearm_length" value="0.39225" /-->
  <!--property name="wrist_1_length" value="0.093" /-->
  <!-- CAD measured -->
  <!--property name="wrist_2_length" value="0.09465" /-->
  <!-- In CAD this distance is 0.930, but in the spec it is 0.09465 -->
  <!--property name="wrist_3_length" value="0.0823" /-->
  <!-- manually measured -->
  <link name="base_link">
    <visual>
      <geometry>
        <mesh filename="package://ur_description/meshes/ur5/visual/base.dae"/>
      </geometry>
      <material name="LightGrey">
        <color rgba="0.7 0.7 0.7 1.0"/>
      </material>
    </visual>
    <collision>
      <geometry>
        <!--           <mesh filename="package://ur_description/meshes/ur5/collision/base.stl" /> -->
        <cylinder length="0.024" radius="0.0735"/>
      </geometry>
    </collision>
    <inertial>
      <mass value="4.0"/>
      <origin rpy="0 0 0" xyz="0.0 0.0 0.0"/>
      <inertia ixx="0.00443333156" ixy="0.0" ixz="0.0" iyy="0.00443333156" iyz="0.0" izz="0.0072"/>
    </inertial>
  </link>
  <joint name="shoulder_pan_joint" type="revolute">
    <parent link="base_link"/>
    <child link="shoulder_link"/>
    <origin rpy="0.0 0.0 0.0" xyz="0.0 0.0 0.089159"/>
    <axis xyz="0 0 1"/>
    <limit effort="150.0" lower="-6.28318530718" upper="6.28318530718" velocity="3.15"/>
    <dynamics damping="0.0" friction="0.0"/>
  </joint>
  <link name="shoulder_link">
    <visual>
      <geometry>
        <mesh filename="package://ur_description/meshes/ur5/visual/shoulder.dae"/>
      </geometry>
      <material name="LightGrey">
        <color rgba="0.7 0.7 0.7 1.0"/>
      </material>
    </visual>
    <collision>
      <geometry>
        <!-- <mesh filename="package://ur_description/meshes/ur5/collision/shoulder.stl" /> -->
        <cylinder length="0.134" radius="0.0595"/>
      </geometry>
    </collision>
    <inertial>
      <mass value="3.7"/>
      <origin rpy="0 0 0" xyz="0.0 0.0 0.0"/>
      <inertia ixx="0.010267495893" ixy="0.0" ixz="0.0" iyy="0.010267495893" iyz="0.0" izz="0.00666"/>
    </inertial>
  </link>
  <joint name="shoulder_lift_joint" type="revolute">
    <parent link="shoulder_link"/>
    <child link="upper_arm_link"/>
    <origin rpy="0.0 0.0 0.0" xyz="0.0 0.13585 0.0"/>
    <axis xyz="0 1 0"/>
    <limit effort="150.0" lower="-6.28318530718" upper="6.28318530718" velocity="3.15"/>
    <dynamics damping="0.0" friction="0.0"/>
  </joint>
  <link name="upper_arm_link">
    <visual>
      <geometry>
        <mesh filename="package://ur_description/meshes/ur5/visual/upperarm.dae"/>
      </geometry>
      <material name="LightGrey">
        <color rgba="0.7 0.7 0.7 1.0"/>
      </material>
    </visual>
    <collision>
      <origin rpy="0 0 0" xyz="0.0 0.0 0.22"/>
      <geometry>
        <!--  <mesh filename="package://ur_description/meshes/ur5/collision/upperarm.stl" /> -->
        <cylinder length="0.545" radius="0.0450"/>
      </geometry>
    </collision>
    <inertial>
      <mass value="8.393"/>
      <origin rpy="0 0 0" xyz="0.0 0.0 0.28"/>
      <inertia ixx="0.22689067591" ixy="0.0" ixz="0.0" iyy="0.22689067591" iyz="0.0" izz="0.0151074"/>
    </inertial>
  </link>
  <joint name="elbow_joint" type="revolute">
    <parent link="upper_arm_link"/>
    <child link="forearm_link"/>
    <origin rpy="0.0 2.09439510239 0.0" xyz="0.0 -0.1197 0.425"/>
    <axis xyz="0 1 0"/>
    <limit effort="150.0" lower="-3.14159265359" upper="3.14159265359" velocity="3.15"/>
    <dynamics damping="0.0" friction="0.0"/>
  </joint>
  <link name="forearm_link">
    <visual>
      <geometry>
        <mesh filename="package://ur_description/meshes/ur5/visual/forearm.dae"/>
      </geometry>
      <material name="LightGrey">
        <color rgba="0.7 0.7 0.7 1.0"/>
      </material>
    </visual>
    <collision>
      <origin rpy="0 0 0" xyz="0.0 0.0 0.18"/>
      <geometry>
        <!--  <mesh filename="package://ur_description/meshes/ur5/collision/forearm.stl" /> -->
        <cylinder length="0.489" radius="0.0380"/>
      </geometry>
    </collision>
    <inertial>
      <mass value="2.275"/>
      <origin rpy="0 0 0" xyz="0.0 0.0 0.196125"/>
      <inertia ixx="0.0312167910289" ixy="0.0" ixz="0.0" iyy="0.0312167910289" iyz="0.0" izz="0.004095"/>
    </inertial>
  </link>
  <joint name="wrist_1_joint" type="revolute">
    <parent link="forearm_link"/>
    <child link="wrist_1_link"/>
    <origin rpy="0.0 1.57079632679 0.0" xyz="0.0 0.0 0.39225"/>
    <axis xyz="0 1 0"/>
    <limit effort="28.0" lower="-6.28318530718" upper="6.28318530718" velocity="3.2"/>
    <dynamics damping="0.0" friction="0.0"/>
  </joint>
  <link name="wrist_1_link">
    <visual>
      <geometry>
        <mesh filename="package://ur_description/meshes/ur5/visual/wrist1.dae"/>
      </geometry>
      <material name="LightGrey">
        <color rgba="0.7 0.7 0.7 1.0"/>
      </material>
    </visual>
    <collision>
      <origin rpy="0 0 0" xyz="0.0 0.093 0.008"/>
      <geometry>
        <!--  <mesh filename="package://ur_description/meshes/ur5/collision/wrist1.stl" /> -->
        <cylinder length="0.100" radius="0.0320"/>
      </geometry>
    </collision>
    <inertial>
      <mass value="1.219"/>
      <origin rpy="0 0 0" xyz="0.0 0.093 0.0"/>
      <inertia ixx="0.00255989897604" ixy="0.0" ixz="0.0" iyy="0.00255989897604" iyz="0.0" izz="0.0021942"/>
    </inertial>
  </link>
  <joint name="wrist_2_joint" type="revolute">
    <parent link="wrist_1_link"/>
    <child link="wrist_2_link"/>
    <origin rpy="0.0 0.0 0.0" xyz="0.0 0.093 0.0"/>
    <axis xyz="0 0 1"/>
    <limit effort="28.0" lower="-6.28318530718" upper="6.28318530718" velocity="3.2"/>
    <dynamics damping="0.0" friction="0.0"/>
  </joint>
  <link name="wrist_2_link">
    <visual>
      <geometry>
        <mesh filename="package://ur_description/meshes/ur5/visual/wrist2.dae"/>
      </geometry>
      <material name="LightGrey">
        <color rgba="0.7 0.7 0.7 1.0"/>
      </material>
    </visual>
    <collision>
      <origin rpy="1.57 0 0" xyz="0.0 0.0 0.09465"/>
      <geometry>
        <!--  <mesh filename="package://ur_description/meshes/ur5/collision/wrist2.stl" /> -->
        <cylinder length="0.105" radius="0.0320"/>
      </geometry>
    </collision>
    <inertial>
      <mass value="1.219"/>
      <origin rpy="0 0 0" xyz="0.0 0.0 0.09465"/>
      <inertia ixx="0.00255989897604" ixy="0.0" ixz="0.0" iyy="0.00255989897604" iyz="0.0" izz="0.0021942"/>
    </inertial>
  </link>
  <joint name="wrist_3_joint" type="revolute">
    <parent link="wrist_2_link"/>
    <child link="wrist_3_link"/>
    <origin rpy="0.0 0.0 0.0" xyz="0.0 0.0 0.09465"/>
    <axis xyz="0 1 0"/>
    <limit effort="28.0" lower="-6.28318530718" upper="6.28318530718" velocity="3.2"/>
    <dynamics damping="0.0" friction="0.0"/>
  </joint>
  <link name="wrist_3_link">
    <visual>
      <geometry>
        <mesh filename="package://ur_description/meshes/ur5/visual/wrist3.dae"/>
      </geometry>
      <material name="LightGrey">
        <color rgba="0.7 0.7 0.7 1.0"/>
      </material>
    </visual>
    <collision>
      <origin rpy="1.57 0.0 0" xyz="0.0 0.067 0.0"/>
      <geometry>
        <!--  <mesh filename="package://ur_description/meshes/ur5/collision/wrist3.stl" /> -->
        <cylinder length="0.0245" radius="0.0320"/>
      </geometry>
    </collision>
    <inertial>
      <mass value="0.1879"/>
      <origin rpy="1.57079632679 0 0" xyz="0.0 0.06505 0.0"/>
      <inertia ixx="8.46958911216e-05" ixy="0.0" ixz="0.0" iyy="8.46958911216e-05" iyz="0.0" izz="0.0001321171875"/>
    </inertial>
  </link>
  <joint name="ee_fixed_joint" type="fixed">
    <parent link="wrist_3_link"/>
    <child link="ee_link"/>
    <origin rpy="0.0 0.0 1.57079632679" xyz="0.0 0.0823 0.0"/>
  </joint>
  <link name="ee_link">
    <collision>
      <geometry>
        <box size="0.01 0.01 0.01"/>
      </geometry>
      <origin rpy="0 0 0" xyz="-0.01 0 0"/>
    </collision>
  </link>
  <transmission name="shoulder_pan_trans">
    <type>transmission_interface/SimpleTransmission</type>
    <joint name="shoulder_pan_joint">
      <hardwareInterface>hardware_interface/PositionJointInterface</hardwareInterface>
    </joint>
    <actuator name="shoulder_pan_motor">
      <mechanicalReduction>1</mechanicalReduction>
    </actuator>
  </transmission>
  <transmission name="shoulder_lift_trans">
    <type>transmission_interface/SimpleTransmission</type>
    <joint name="shoulder_lift_joint">
      <hardwareInterface>hardware_interface/PositionJointInterface</hardwareInterface>
    </joint>
    <actuator name="shoulder_lift_motor">
      <mechanicalReduction>1</mechanicalReduction>
    </actuator>
  </transmission>
  <transmission name="elbow_trans">
    <type>transmission_interface/SimpleTransmission</type>
    <joint name="elbow_joint">
      <hardwareInterface>hardware_interface/PositionJointInterface</hardwareInterface>
    </joint>
    <actuator name="elbow_motor">
      <mechanicalReduction>1</mechanicalReduction>
    </actuator>
  </transmission>
  <transmission name="wrist_1_trans">
    <type>transmission_interface/SimpleTransmission</type>
    <joint name="wrist_1_joint">
      <hardwareInterface>hardware_interface/PositionJointInterface</hardwareInterface>
    </joint>
    <actuator name="wrist_1_motor">
      <mechanicalReduction>1</mechanicalReduction>
    </actuator>
  </transmission>
  <transmission name="wrist_2_trans">
    <type>transmission_interface/SimpleTransmission</type>
    <joint name="wrist_2_joint">
      <hardwareInterface>hardware_interface/PositionJointInterface</hardwareInterface>
    </joint>
    <actuator name="wrist_2_motor">
      <mechanicalReduction>1</mechanicalReduction>
    </actuator>
  </transmission>
  <transmission name="wrist_3_trans">
    <type>transmission_interface/SimpleTransmission</type>
    <joint name="wrist_3_joint">
      <hardwareInterface>hardware_interface/PositionJointInterface</hardwareInterface>
    </joint>
    <actuator name="wrist_3_motor">
      <mechanicalReduction>1</mechanicalReduction>
    </actuator>
  </transmission>
  <gazebo reference="shoulder_link">
    <selfCollide>true</selfCollide>
  </gazebo>
  <gazebo reference="upper_arm_link">
    <selfCollide>true</selfCollide>
  </gazebo>
  <gazebo reference="forearm_link">
    <selfCollide>true</selfCollide>
  </gazebo>
  <gazebo reference="wrist_1_link">
    <selfCollide>true</selfCollide>
  </gazebo>
  <gazebo reference="wrist_3_link">
    <selfCollide>true</selfCollide>
  </gazebo>
  <gazebo reference="wrist_2_link">
    <selfCollide>true</selfCollide>
  </gazebo>
  <gazebo reference="ee_link">
    <selfCollide>true</selfCollide>
  </gazebo>
  <!-- ROS base_link to UR 'Base' Coordinates transform -->
  <link name="base"/>
  <joint name="base_link-base_fixed_joint" type="fixed">
    <!-- NOTE: this rotation is only needed as long as base_link itself is
                 not corrected wrt the real robot (ie: rotated over 180
                 degrees)
      -->
    <origin rpy="0 0 -3.14159265359" xyz="0 0 0"/>
    <parent link="base_link"/>
    <child link="base"/>
  </joint>
  <!-- Frame coincident with all-zeros TCP on UR controller -->
  <link name="tool0"/>
  <joint name="wrist_3_link-tool0_fixed_joint" type="fixed">
    <origin rpy="-1.57079632679 0 0" xyz="0 0.0823 0"/>
    <parent link="wrist_3_link"/>
    <child link="tool0"/>
  </joint>
  <joint name="ebot_joint" type="fixed">
    <parent link="ebot_base"/>
    <child link="base_link"/>
    <origin rpy="0.0 0.0 0" xyz="0 0 0.521"/>
    <!--576 height from ground-->
  </joint>
  <joint name="gripper_base_joint" type="fixed">
    <parent link="wrist_3_link"/>
    <child link="gripper_base_link"/>
    <origin rpy="0 0 1.57079632679" xyz="0 0.1 0"/>
  </joint>
  <link name="gripper_base_link">
    <visual>
      <geometry>
        <mesh filename="package://robotiq_85_description/meshes/visual/robotiq_85_base_link.dae"/>
      </geometry>
    </visual>
    <collision>
      <origin rpy="0 1.57 0" xyz="0.017 0 0"/>
      <geometry>
        <!-- <mesh filename="package://robotiq_85_description/meshes/collision/robotiq_85_base_link.stl"/> -->
        <cylinder length="0.030" radius="0.0375"/>
      </geometry>
    </collision>
    <inertial>
      <mass value="0.636951"/>
      <origin xyz="0.0 0.0 0.0"/>
      <inertia ixx="0.000380" ixy="0.000000" ixz="0.000000" iyx="0.000000" iyy="0.001110" iyz="0.000000" izx="0.000000" izy="0.000000" izz="0.001171"/>
    </inertial>
  </link>
  <gazebo reference="gripper_base_link">
    <implicitSpringDamper>1</implicitSpringDamper>
    <mu1>100000</mu1>
    <mu2>100000</mu2>
    <kp>100000000.0</kp>
    <kd>1.0</kd>
  </gazebo>
  <joint name="gripper_finger1_joint" type="revolute">
    <parent link="gripper_base_link"/>
    <child link="gripper_finger1_knuckle_link"/>
    <axis xyz="0 0 1"/>
    <origin rpy="3.14159265359 0.0 0.0" xyz="0.05490451627 0.03060114443 0.0"/>
    <limit effort="1000" lower="0.0" upper="0.804" velocity="2.0"/>
  </joint>
  <joint name="gripper_finger2_joint" type="revolute">
    <parent link="gripper_base_link"/>
    <child link="gripper_finger2_knuckle_link"/>
    <axis xyz="0 0 1"/>
    <origin rpy="0.0 0.0 0.0" xyz="0.05490451627 -0.03060114443 0.0"/>
    <limit effort="1000" lower="-3.14" upper="3.14" velocity="100.0"/>
    <mimic joint="gripper_finger1_joint"/>
  </joint>
  <link name="gripper_finger1_knuckle_link">
    <visual>
      <geometry>
        <mesh filename="package://robotiq_85_description/meshes/visual/robotiq_85_knuckle_link.dae"/>
      </geometry>
    </visual>
    <collision>
      <origin rpy="0 0 -0.0873" xyz="0 -0.01 0"/>
      <geometry>
        <!-- <mesh filename="package://robotiq_85_description/meshes/collision/robotiq_85_knuckle_link.stl"/> -->
        <box size="0.012 0.035 0.014"/>
      </geometry>
    </collision>
    <inertial>
      <mass value="0.018491"/>
      <origin xyz="0.0 0.0 0.0"/>
      <inertia ixx="0.000009" ixy="-0.000001" ixz="0.000000" iyx="-0.000001" iyy="0.000001" iyz="0.000000" izx="0.000000" izy="0.000000" izz="0.000010"/>
    </inertial>
  </link>
  <gazebo reference="gripper_finger1_knuckle_link">
    <implicitSpringDamper>1</implicitSpringDamper>
    <mu1>100000</mu1>
    <mu2>100000</mu2>
    <kp>100000000.0</kp>
    <kd>1.0</kd>
  </gazebo>
  <link name="gripper_finger2_knuckle_link">
    <visual>
      <geometry>
        <mesh filename="package://robotiq_85_description/meshes/visual/robotiq_85_knuckle_link.dae"/>
      </geometry>
    </visual>
    <collision>
      <origin rpy="0 0 -0.0873" xyz="0 -0.01 0"/>
      <geometry>
        <!-- <mesh filename="package://robotiq_85_description/meshes/collision/robotiq_85_knuckle_link.stl"/> -->
        <box size="0.012 0.035 0.014"/>
      </geometry>
    </collision>
    <inertial>
      <mass value="0.018491"/>
      <origin xyz="0.0 0.0 0.0"/>
      <inertia ixx="0.000009" ixy="-0.000001" ixz="0.000000" iyx="-0.000001" iyy="0.000001" iyz="0.000000" izx="0.000000" izy="0.000000" izz="0.000010"/>
    </inertial>
  </link>
  <gazebo reference="gripper_finger2_knuckle_link">
    <implicitSpringDamper>1</implicitSpringDamper>
    <mu1>100000</mu1>
    <mu2>100000</mu2>
    <kp>100000000.0</kp>
    <kd>1.0</kd>
  </gazebo>
  <joint name="gripper_finger1_finger_joint" type="fixed">
    <parent link="gripper_finger1_knuckle_link"/>
    <child link="gripper_finger1_finger_link"/>
    <origin rpy="0 0 0" xyz="-0.00408552455 -0.03148604435 0.0"/>
  </joint>
  <joint name="gripper_finger2_finger_joint" type="fixed">
    <parent link="gripper_finger2_knuckle_link"/>
    <child link="gripper_finger2_finger_link"/>
    <origin rpy="0 0 0" xyz="-0.00408552455 -0.03148604435 0.0"/>
  </joint>
  <link name="gripper_finger1_finger_link">
    <visual>
      <geometry>
        <mesh filename="package://robotiq_85_description/meshes/visual/robotiq_85_finger_link.dae"/>
      </geometry>
    </visual>
    <collision>
      <origin rpy="0 0 -0.175" xyz="0.025 -0.002 0"/>
      <geometry>
        <!--  <mesh filename="package://robotiq_85_description/meshes/collision/robotiq_85_finger_link.stl"/> -->
        <box size="0.0591 0.010 0.020"/>
      </geometry>
    </collision>
    <inertial>
      <mass value="0.027309"/>
      <origin xyz="0.0 0.0 0.0"/>
      <inertia ixx="0.000003" ixy="-0.000002" ixz="0.000000" iyx="-0.000002" iyy="0.000021" iyz="0.000000" izx="0.000000" izy="0.000000" izz="0.000020"/>
    </inertial>
  </link>
  <gazebo reference="gripper_finger1_finger_link">
    <implicitSpringDamper>1</implicitSpringDamper>
    <mu1>100000</mu1>
    <mu2>100000</mu2>
    <kp>100000000.0</kp>
    <kd>1.0</kd>
  </gazebo>
  <link name="gripper_finger2_finger_link">
    <visual>
      <geometry>
        <mesh filename="package://robotiq_85_description/meshes/visual/robotiq_85_finger_link.dae"/>
      </geometry>
    </visual>
    <collision>
      <origin rpy="0 0 -0.175" xyz="0.025 -0.002 0"/>
      <geometry>
        <!--  <mesh filename="package://robotiq_85_description/meshes/collision/robotiq_85_finger_link.stl"/> -->
        <box size="0.0591 0.010 0.020"/>
      </geometry>
    </collision>
    <inertial>
      <mass value="0.027309"/>
      <origin xyz="0.0 0.0 0.0"/>
      <inertia ixx="0.000003" ixy="-0.000002" ixz="0.000000" iyx="-0.000002" iyy="0.000021" iyz="0.000000" izx="0.000000" izy="0.000000" izz="0.000020"/>
    </inertial>
  </link>
  <gazebo reference="gripper_finger2_finger_link">
    <implicitSpringDamper>1</implicitSpringDamper>
    <mu1>100000</mu1>
    <mu2>100000</mu2>
    <kp>100000000.0</kp>
    <kd>1.0</kd>
  </gazebo>
  <joint name="gripper_finger1_inner_knuckle_joint" type="continuous">
    <parent link="gripper_base_link"/>
    <child link="gripper_finger1_inner_knuckle_link"/>
    <axis xyz="0 0 1"/>
    <origin rpy="3.14159265359 0.0 0.0" xyz="0.06142 0.0127 0"/>
    <limit effort="0.1" lower="-3.14" upper="3.14" velocity="100.0"/>
    <mimic joint="gripper_finger1_joint" offset="0"/>
  </joint>
  <joint name="gripper_finger2_inner_knuckle_joint" type="continuous">
    <parent link="gripper_base_link"/>
    <child link="gripper_finger2_inner_knuckle_link"/>
    <axis xyz="0 0 1"/>
    <origin rpy="0 0 0" xyz="0.06142 -0.0127 0"/>
    <limit effort="0.1" lower="-3.14" upper="3.14" velocity="100.0"/>
    <mimic joint="gripper_finger1_joint" offset="0"/>
  </joint>
  <link name="gripper_finger1_inner_knuckle_link">
    <visual>
      <geometry>
        <mesh filename="package://robotiq_85_description/meshes/visual/robotiq_85_inner_knuckle_link.dae"/>
      </geometry>
    </visual>
    <collision>
      <origin rpy="0 0 -0.698" xyz="0.025 -0.02 0"/>
      <geometry>
        <!--    <mesh filename="package://robotiq_85_description/meshes/collision/robotiq_85_inner_knuckle_link.stl"/> -->
        <box size="0.055 0.006 0.020"/>
      </geometry>
    </collision>
    <inertial>
      <mass value="0.029951"/>
      <origin xyz="0.0 0.0 0.0"/>
      <inertia ixx="0.000039" ixy="0.000000" ixz="0.000000" iyx="0.000000" iyy="0.000005" iyz="0.000000" izx="0.000000" izy="0.000000" izz="0.000035"/>
    </inertial>
  </link>
  <gazebo reference="gripper_finger1_inner_knuckle_link">
    <implicitSpringDamper>1</implicitSpringDamper>
    <mu1>100000</mu1>
    <mu2>100000</mu2>
    <kp>100000000.0</kp>
    <kd>1.0</kd>
  </gazebo>
  <link name="gripper_finger2_inner_knuckle_link">
    <visual>
      <geometry>
        <mesh filename="package://robotiq_85_description/meshes/visual/robotiq_85_inner_knuckle_link.dae"/>
      </geometry>
    </visual>
    <collision>
      <origin rpy="0 0 -0.698" xyz="0.025 -0.02 0"/>
      <geometry>
        <!--   <mesh filename="package://robotiq_85_description/meshes/collision/robotiq_85_inner_knuckle_link.stl"/> -->
        <box size="0.055 0.006 0.020"/>
      </geometry>
    </collision>
    <inertial>
      <mass value="0.029951"/>
      <origin xyz="0.0 0.0 0.0"/>
      <inertia ixx="0.000039" ixy="0.000000" ixz="0.000000" iyx="0.000000" iyy="0.000005" iyz="0.000000" izx="0.000000" izy="0.000000" izz="0.000035"/>
    </inertial>
  </link>
  <gazebo reference="gripper_finger2_inner_knuckle_link">
    <implicitSpringDamper>1</implicitSpringDamper>
    <mu1>100000</mu1>
    <mu2>100000</mu2>
    <kp>100000000.0</kp>
    <kd>1.0</kd>
  </gazebo>
  <joint name="gripper_finger1_finger_tip_joint" type="continuous">
    <parent link="gripper_finger1_inner_knuckle_link"/>
    <child link="gripper_finger1_finger_tip_link"/>
    <axis xyz="0 0 1"/>
    <origin rpy="0.0 0.0 0.0" xyz="0.04303959807 -0.03759940821 0.0"/>
    <limit effort="0.1" lower="-3.14" upper="3.14" velocity="100.0"/>
    <mimic joint="gripper_finger1_joint" multiplier="-1"/>
  </joint>
  <joint name="gripper_finger2_finger_tip_joint" type="continuous">
    <parent link="gripper_finger2_inner_knuckle_link"/>
    <child link="gripper_finger2_finger_tip_link"/>
    <axis xyz="0 0 1"/>
    <origin rpy="0.0 0.0 0.0" xyz="0.04303959807 -0.03759940821  0.0"/>
    <limit effort="0.1" lower="-3.14" upper="3.14" velocity="100.0"/>
    <mimic joint="gripper_finger1_joint" multiplier="-1"/>
  </joint>
  <link name="gripper_finger1_finger_tip_link">
    <visual>
      <geometry>
        <mesh filename="package://robotiq_85_description/meshes/visual/robotiq_85_finger_tip_link.dae"/>
      </geometry>
    </visual>
    <collision>
      <origin rpy="0 0 0" xyz="0.02 0 0"/>
      <geometry>
        <!--  <mesh filename="package://robotiq_85_description/meshes/collision/robotiq_85_finger_tip_link.stl"/> -->
        <box size="0.045 0.01 0.02"/>
      </geometry>
    </collision>
    <inertial>
      <mass value="0.019555"/>
      <origin xyz="0.0 0.0 0.0"/>
      <inertia ixx="0.000002" ixy="0.000000" ixz="0.000000" iyx="0.000000" iyy="0.000005" iyz="0.000000" izx="0.000000" izy="0.000000" izz="0.000006"/>
    </inertial>
  </link>
  <gazebo reference="gripper_finger1_finger_tip_link">
    <implicitSpringDamper>1</implicitSpringDamper>
    <mu1>100000</mu1>
    <mu2>100000</mu2>
    <kp>100000000.0</kp>
    <kd>1.0</kd>
  </gazebo>
  <link name="gripper_finger2_finger_tip_link">
    <visual>
      <geometry>
        <mesh filename="package://robotiq_85_description/meshes/visual/robotiq_85_finger_tip_link.dae"/>
      </geometry>
    </visual>
    <collision>
      <origin rpy="0 0 0" xyz="0.02 0 0"/>
      <geometry>
        <!-- <mesh filename="package://robotiq_85_description/meshes/collision/robotiq_85_finger_tip_link.stl"/> -->
        <box size="0.045 0.01 0.02"/>
      </geometry>
    </collision>
    <inertial>
      <mass value="0.019555"/>
      <origin xyz="0.0 0.0 0.0"/>
      <inertia ixx="0.000002" ixy="0.000000" ixz="0.000000" iyx="0.000000" iyy="0.000005" iyz="0.000000" izx="0.000000" izy="0.000000" izz="0.000006"/>
    </inertial>
  </link>
  <gazebo reference="gripper_finger2_finger_tip_link">
    <implicitSpringDamper>1</implicitSpringDamper>
    <mu1>100000</mu1>
    <mu2>100000</mu2>
    <kp>100000000.0</kp>
    <kd>1.0</kd>
  </gazebo>
  <gazebo>
    <plugin filename="libgazebo_grasp_fix.so" name="gazebo_grasp_fix">
      <arm>
        <arm_name>gripper_arm</arm_name>
        <palm_link>wrist_3_link</palm_link>
        <gripper_link>gripper_finger1_finger_tip_link</gripper_link>
        <gripper_link>gripper_finger2_finger_tip_link</gripper_link>
      </arm>
      <forces_angle_tolerance>100</forces_angle_tolerance>
      <update_rate>2</update_rate>
      <grip_count_threshold>1</grip_count_threshold>
      <max_grip_count>2</max_grip_count>
      <release_tolerance>0.005</release_tolerance>
      <disable_collisions_on_attach>true</disable_collisions_on_attach>
      <contact_topic>__default_topic__</contact_topic>
    </plugin>
  </gazebo>
  <transmission name="gripper_finger1_trans">
    <type>transmission_interface/SimpleTransmission</type>
    <joint name="gripper_finger1_joint">
      <hardwareInterface>PositionJointInterface</hardwareInterface>
    </joint>
    <actuator name="gripper_finger1_motor">
      <mechanicalReduction>1</mechanicalReduction>
      <hardwareInterface>PositionJointInterface</hardwareInterface>
    </actuator>
  </transmission>
  <gazebo>
    <!-- loading plugin: mimic joints works in gazebo now -->
    <plugin filename="libroboticsgroup_gazebo_mimic_joint_plugin.so" name="mimic_robotiq_85_1">
      <joint>gripper_finger1_joint</joint>
      <mimicJoint>gripper_finger2_joint</mimicJoint>
      <!--multiplier>1.0</multiplier>
                <offset>0.0</offset-->
    </plugin>
    <plugin filename="libroboticsgroup_gazebo_mimic_joint_plugin.so" name="mimic_robotiq_85_2">
      <joint>gripper_finger1_joint</joint>
      <mimicJoint>gripper_finger2_inner_knuckle_joint</mimicJoint>
      <!--multiplier>1.0</multiplier>
                <offset>0.0</offset-->
    </plugin>
    <plugin filename="libroboticsgroup_gazebo_mimic_joint_plugin.so" name="mimic_robotiq_85_3">
      <joint>gripper_finger1_joint</joint>
      <mimicJoint>gripper_finger1_inner_knuckle_joint</mimicJoint>
      <!--multiplier>1.0</multiplier>
                <offset>0.0</offset-->
    </plugin>
    <plugin filename="libroboticsgroup_gazebo_mimic_joint_plugin.so" name="mimic_robotiq_85_4">
      <joint>gripper_finger1_joint</joint>
      <mimicJoint>gripper_finger1_finger_tip_joint</mimicJoint>
      <multiplier>-1.0</multiplier>
      <offset>0.0</offset>
    </plugin>
    <plugin filename="libroboticsgroup_gazebo_mimic_joint_plugin.so" name="mimic_robotiq_85_5">
      <joint>gripper_finger1_joint</joint>
      <mimicJoint>gripper_finger2_finger_tip_joint</mimicJoint>
      <multiplier>-1.0</multiplier>
      <offset>0.0</offset>
    </plugin>
  </gazebo>
  <!-- realsense camera for arm-->
  <joint name="intelrealsense2" type="fixed">
    <axis xyz="0 0 0"/>
    <origin rpy="3.14 0 1.57" xyz="0 0.1 -0.08"/>
    <parent link="wrist_3_link"/>
    <child link="camera_link2"/>
  </joint>
  <link name="camera_link2">
    <collision>
      <origin rpy="0 0 0" xyz="0.02 0 0"/>
      <geometry>
        <box size="0.001 0.001 0.001"/>
      </geometry>
    </collision>
    <visual>
      <origin rpy="1.5707 0 1.5707" xyz="0 0 0"/>
      <geometry>
        <mesh filename="package://ebot_description/meshes/NAVRS.STL"/>
      </geometry>
    </visual>
    <inertial>
      <mass value="1e-5"/>
      <origin rpy="0 0 0" xyz="0 0 0"/>
      <inertia ixx="0" ixy="0" ixz="0" iyy="0" iyz="0" izz="0"/>
    </inertial>
  </link>
  <joint name="camera_optical_joint2" type="fixed">
    <origin rpy="-1.57079632679 0 -1.57079632679" xyz="0 0 0"/>
    <parent link="camera_link2"/>
    <child link="camera_rgb_frame2"/>
  </joint>
  <link name="camera_rgb_frame2">
  </link>
  <joint name="camera_depth_joint2" type="fixed">
    <origin rpy="-1.57079632679 0 -1.57079632679" xyz="0 0 0"/>
    <parent link="camera_link2"/>
    <child link="camera_depth_frame2"/>
  </joint>
  <link name="camera_depth_frame2">
  </link>
  <gazebo reference="camera_link2">
    <sensor name="intelrealsense2" type="depth">
      <always_on>1</always_on>
      <visualize>true</visualize>
      <camera>
        <horizontal_fov>1.047</horizontal_fov>
        <image>
          <width>640</width>
          <height>480</height>
          <format>R8G8B8</format>
        </image>
        <depth_camera>

        </depth_camera>
        <clip>
          <near>0.1</near>
          <far>100</far>
        </clip>
      </camera>
      <plugin filename="libgazebo_ros_openni_kinect.so" name="intelrealsense">
        <alwaysOn>true</alwaysOn>
        <updateRate>10.0</updateRate>
        <cameraName>camera2</cameraName>
        <frameName>camera_depth_frame2</frameName>
        <imageTopicName>/camera/color/image_raw2</imageTopicName>
        <depthImageTopicName>/camera/depth/image_raw2</depthImageTopicName>
        <pointCloudTopicName>depth/points2</pointCloudTopicName>
        <cameraInfoTopicName>/camera/color/camera_info2</cameraInfoTopicName>
        <depthImageCameraInfoTopicName>/camera/depth/camera_info2</depthImageCameraInfoTopicName>
        <pointCloudCutoff>0.2</pointCloudCutoff>
        <pointCloudCutoffMax>10.0</pointCloudCutoffMax>
        <hackBaseline>0.07</hackBaseline>
        <distortionK1>0.0</distortionK1>
        <distortionK2>0.0</distortionK2>
        <distortionK3>0.0</distortionK3>
        <distortionT1>0.0</distortionT1>
        <distortionT2>0.0</distortionT2>
        <CxPrime>0.0</CxPrime>
        <Cx>0.0</Cx>
        <Cy>0.0</Cy>
        <focalLength>0.0</focalLength>
      </plugin>
    </sensor>
  </gazebo>
  <!-- fixed realsense -->
  <!--  <joint name="intelrealsense3" type="fixed">
    <axis xyz="0 0 0" />
    <origin xyz="0 0 1.5" rpy="3.14 0.52 0"/>
    <parent link="ebot_base"/>
    <child link="camera_link3"/>
  </joint>
<link name="camera_link3">
    <collision>
      <origin xyz="0.02 0 0" rpy="0 0 0"/>
      <geometry>
        <box size="0.001 0.001 0.001"/>
      </geometry>
    </collision>

    <visual>
      <origin xyz="0 0 0" rpy="1.5707 0 1.5707"/>
      <geometry>
         <mesh filename="package://ebot_description/meshes/NAVRS.STL" />
      </geometry>
    </visual>

    <inertial>
      <mass value="1e-5" />
      <origin xyz="0 0 0" rpy="0 0 0"/>
      <inertia ixx="0" ixy="0" ixz="0" iyy="0" iyz="0" izz="0" />
    </inertial>
  </link>


  <joint name="camera_optical_joint3" type="fixed">
    <origin xyz="0 0 0" rpy="${-pi/2} 0 ${-pi/2}"/>
    <parent link="camera_link3"/>
    <child link="camera_rgb_frame3"/>
  </joint>

  <link name="camera_rgb_frame3">
  </link>

  <joint name="camera_depth_joint3" type="fixed">
    <origin xyz="0 0 0" rpy="${-pi/2} 0 ${-pi/2}"/>
    <parent link="camera_link3"/>
    <child link="camera_depth_frame3"/>
  </joint>

    <link name="camera_depth_frame3">
  </link>


<gazebo reference="camera_link3">
    <sensor type="depth" name="intelrealsense2">
      <always_on>1</always_on>
      <visualize>true</visualize>
      <camera>
        <horizontal_fov>1.047</horizontal_fov>
        <image>
          <width>640</width>
          <height>480</height>
          <format>R8G8B8</format>
        </image>
        <depth_camera>

        </depth_camera>
        <clip>
          <near>0.1</near>
          <far>100</far>
        </clip>
      </camera>
      <plugin name="intelrealsense" filename="libgazebo_ros_openni_kinect.so">
        <alwaysOn>true</alwaysOn>
        <updateRate>10.0</updateRate>
        <cameraName>camera3</cameraName>
        <frameName>camera_depth_frame3</frameName>
        <imageTopicName>/camera/color/image_raw3</imageTopicName>
        <depthImageTopicName>/camera/depth/image_raw3</depthImageTopicName>
        <pointCloudTopicName>depth/points3</pointCloudTopicName>
        <cameraInfoTopicName>/camera/color/camera_info3</cameraInfoTopicName>
        <depthImageCameraInfoTopicName>/camera/depth/camera_info3</depthImageCameraInfoTopicName>
         <pointCloudCutoff>0.2</pointCloudCutoff>
         <pointCloudCutoffMax>10.0</pointCloudCutoffMax>
        <hackBaseline>0.07</hackBaseline>
        <distortionK1>0.0</distortionK1>
        <distortionK2>0.0</distortionK2>
        <distortionK3>0.0</distortionK3>
        <distortionT1>0.0</distortionT1>
        <distortionT2>0.0</distortionT2>
        <CxPrime>0.0</CxPrime>
        <Cx>0.0</Cx>
        <Cy>0.0</Cy>
        <focalLength>0.0</focalLength>
      </plugin>
    </sensor>
  </gazebo>
 -->
</robot>

